<?xml version='1.0'?>
<sdf version='1.4'>
  <model name="my_robot">
  
 <static>true</static> 
   
  <!-- Rectangular base -->
  <link name='torso'>
    <pose>0 0 0 0 0 0</pose>
     <collision name='collision'>
      <geometry>
        <box>
         <size> 0.1651 0.26035 0.1524</size>
        </box>
      </geometry>
     </collision>

     <visual name='visual'>
      <geometry>
       <box>
         <size> 0.1651 0.26035 0.1524</size>
       </box>
      </geometry>
    </visual>
 </link>


<link name="LSP_body">
 <pose>0.0 0.245510  0.0 0 0.0 0.0</pose>

 <collision name="collision">
   <geometry>
     <sphere>
      <radius>0.06985</radius>
     </sphere>
   </geometry>
 </collision>
 <visual name="visual">
   <geometry>
     <sphere>
      <radius>0.06985</radius>
     </sphere>
   </geometry>
  <material>
    <ambient>0 0 1 1</ambient>
    <diffuse>0 0 1 1</diffuse>
    <specular>0.1 0.1 0.1 1</specular>
    <emissive>0 0 0 0</emissive>
  </material>
 </visual>
</link>
<joint type="revolute" name="LSP">
        <pose>0 0.0 0 0 0  0</pose>
        <child>LSP_body</child>
        <parent>torso</parent>
        <axis>
          <xyz>0 1 0</xyz>
        </axis>
</joint>


<link name="LSR_body">
 <pose>0.0 0.2455100  0.0 0 0.0 0.0</pose>
 <visual name="visual">
   <geometry>
     <sphere>
      <radius>0.06985</radius>
     </sphere>
   </geometry>
  <material>
    <ambient>0 1 0 1</ambient>
    <diffuse>0 1 0 1</diffuse>
    <specular>0.1 0.1 0.1 1</specular>
    <emissive>0 0 0 0</emissive>
  </material>
 </visual>
</link>


<joint type="revolute" name="LSR">
 <pose>0.0 0.0 0.0 0 0.0 0.0</pose>
        <child>LSR_body</child>
        <parent>LSP_body</parent>
        <axis>
          <xyz>1 0 0</xyz>
        </axis>
</joint>



<link name="LSY_body">
 <pose>0.0 0.2455100  0.0 0 0.0 0.0</pose>
 <visual name="visual">
   <geometry>
     <sphere>
      <radius>0.06985</radius>
     </sphere>
   </geometry>
 </visual>
</link>

<joint type="revolute" name="LSY">
 <pose>0.0 0.0 0.0 0 0.0 0.0</pose>
        <child>LSY_body</child>
        <parent>LSR_body</parent>
        <axis>
          <xyz>0 0 1</xyz>
        </axis>
</joint>


<link name="LEP_body">
 <!--<pose>0.0 0.2455100  -0.2825750 0 0.0 0.0</pose>-->
 <pose>0.0 0.2455100  -0.2825750 0 0.0 0.0</pose>
 <collision name="collision">
   <geometry>
     <sphere>
      <radius>0.025111</radius>
     </sphere>
   </geometry>
 </collision>
 <visual name="visual">
   <geometry>
     <sphere>
      <radius>0.025111</radius>
     </sphere>
   </geometry>
  <material>
    <ambient>0 0 1 1</ambient>
    <diffuse>0 0 1 1</diffuse>
    <specular>0.1 0.1 0.1 1</specular>
    <emissive>0 0 0 0</emissive>
  </material>
 </visual>
</link>
<joint type="revolute" name="LEP">
 <pose>0.0 0.0 0.0 0 0.0 0.0</pose>
        <child>LEP_body</child>
        <parent>LSY_body</parent>
        <axis>
          <xyz>0 1 0</xyz>
        </axis>
</joint>






<link name="LWY_body">
 <!--<pose>0.0 0.2455100  -0.2825750 0 0.0 0.0</pose>-->
 <pose>0.0 0.2455100  -0.5953125 0 0.0 0.0</pose>
 <collision name="collision">
   <geometry>
     <sphere>
      <radius>0.025111</radius>
     </sphere>
   </geometry>
 </collision>
 <visual name="visual">
   <geometry>
     <sphere>
      <radius>0.025111</radius>
     </sphere>
   </geometry>
  <material>
    <ambient>0 0 1 1</ambient>
    <diffuse>0 0 1 1</diffuse>
    <specular>0.1 0.1 0.1 1</specular>
    <emissive>0 0 0 0</emissive>
  </material>
 </visual>
</link>
<joint type="revolute" name="LWY">
 <pose>0.0 0.0 0.0 0 0.0 0.0</pose>
        <child>LWY_body</child>
        <parent>LEP_body</parent>
        <axis>
          <xyz>0 0 1</xyz>
        </axis>
</joint>

<link name="LWR_body">
 <!--<pose>0.0 0.2455100  -0.2825750 0 0.0 0.0</pose>-->
 <pose>0.0 0.2455100  -0.5953125 0 0.0 0.0</pose>
 <collision name="collision">
   <geometry>
     <sphere>
      <radius>0.025111</radius>
     </sphere>
   </geometry>
 </collision>
 <visual name="visual">
   <geometry>
     <sphere>
      <radius>0.025111</radius>
     </sphere>
   </geometry>
  <material>
    <ambient>0 0 1 1</ambient>
    <diffuse>0 0 1 1</diffuse>
    <specular>0.1 0.1 0.1 1</specular>
    <emissive>0 0 0 0</emissive>
  </material>
 </visual>
</link>
<joint type="revolute" name="LWR">
 <pose>0.0 0.0 0.0 0 0.0 0.0</pose>
        <child>LWR_body</child>
        <parent>LWY_body</parent>
        <axis>
          <xyz>1 0 0</xyz>
        </axis>
</joint>



<link name="LHAND_body">
 <!--<pose>0.0 0.2455100  -0.2825750 0 0.0 0.0</pose>-->
 <pose>0.0 0.2455100  -0.6588125 0 0.0 0.0</pose>
 <collision name="collision">
   <geometry>
     <sphere>
      <radius>0.025111</radius>
     </sphere>
   </geometry>
 </collision>
 <visual name="visual">
   <geometry>
     <sphere>
      <radius>0.01</radius>
     </sphere>
   </geometry>
  <material>
    <ambient>0 0 1 1</ambient>
    <diffuse>0 0 1 1</diffuse>
    <specular>0.1 0.1 0.1 1</specular>
    <emissive>0 0 0 0</emissive>
  </material>
 </visual>
</link>
<joint type="revolute" name="LHAND">
 <pose>0.0 0.0 0.0 0 0.0 0.0</pose>
        <child>LHAND_body</child>
        <parent>LWR_body</parent>
        <axis>
          <xyz>1 0 0</xyz>
        </axis>
</joint>


  </model>
</sdf>
